Workbook
Name Taper_rate: #REF!
Name Taper_rate: '[1]DCF Model'!$C$22
Name Tax_rate: '[2]DCF Model'!$C$26
Name Tax_rate: Sheet1!$C$26
Name UPDATE: #REF!
Name UPDATE: 'Data Sheet'!$E$1
Name UPDATE: #REF!

Sheet Sheet1
B2: Financial Modelling
B6: Company Overview
B8: Trent Limited is the retail arm of the Tata Group, operating multiple retail formats including:
B10: Westside - Department store chain (248 stores)
B11: Zudio - Value fashion retail chain (766 stores)
B12: Star Market - Hypermarket format (78 stores)
B14: Total Sore Count: 1000+ stores across 240+ cities | Retail Area: ~ 13.6 million sq ft
B16: Key Assumptions & Methodology
B18: Parameter | C18: Value | D18: Rationale
B19: Valuation Date
B20: Projection Period
B21: Revenue Growth% | C21: 0.2 | D21: Based on management guidance
B22: Annual Growth Tapering | C22: 0.02
B23: Terminal Growth Rate | C23: 0.06 | D23: Conoservative long-term growth considering India's GDP and retail sector potential
B24: Risk-Free Rate (Rf) | C24: 0.065 | D24: 10-year Indian Government Bond yield
B25: Equity Risk Premium (ERP) | C25: =12%-C24 -> 0.055 | D25: Expected return over risk-free rate for equity investors
B26: Tax Rate | C26: 0.25 | D26: Effective tax rate based on historical data
B28: Financial Performance (₹ Crores)
B29: INCOME STATEMENT
B30: Particulars | C30: 2021 | D30: =C30+1 -> 2022 | E30: =D30+1 -> 2023 | F30: =E30+1 -> 2024 | G30: =F30+1 -> 2025
B31: Sales | C31: ='Data Sheet'!G17 -> 2592.96 | D31: ='Data Sheet'!H17 -> 4498.02 | E31: ='Data Sheet'!I17 -> 8242.02 | F31: ='Data Sheet'!J17 -> 12375.11 | G31: ='Data Sheet'!K17 -> 17134.61
B32: % growth | D32: =D31/C31-1 -> 0.73470474 | E32: =E31/D31-1 -> 0.83236624 | F32: =F31/E31-1 -> 0.50146566 | G32: =G31/F31-1 -> 0.38460264
B33: Cost of Goods Sold | C33: =SUM('Data Sheet'!G18,-'Data Sheet'!G19,'Data Sheet'!G20:G21) -> 1675.41 | D33: =SUM('Data Sheet'!H18,-'Data Sheet'!H19,'Data Sheet'!H20:H21) -> 2680.57 | E33: =SUM('Data Sheet'!I18,-'Data Sheet'!I19,'Data Sheet'!I20:I21) -> 5076.01 | F33: =SUM('Data Sheet'!J18,-'Data Sheet'!J19,'Data Sheet'!J20:J21) -> 7452.64 | G33: =SUM('Data Sheet'!K18,-'Data Sheet'!K19,'Data Sheet'!K20:K21) -> 10408.8
B34: % of revenue | C34: =C33/C31 -> 0.646138 | D34: =D33/D31 -> 0.59594444 | E34: =E33/E31 -> 0.61586965 | F34: =F33/F31 -> 0.60222818 | G34: =G33/G31 -> 0.60747224
B35: Gross Profit | C35: =C31-C33 -> 917.55 | D35: =D31-D33 -> 1817.45 | E35: =E31-E33 -> 3166.01 | F35: =F31-F33 -> 4922.47 | G35: =G31-G33 -> 6725.81
B36: % margin | C36: =C35/C31 -> 0.353862 | D36: =D35/D31 -> 0.40405556 | E36: =E35/E31 -> 0.38413035 | F36: =F35/F31 -> 0.39777182 | G36: =G35/G31 -> 0.39252776
B37: Operating Expenses | C37: =SUM('Data Sheet'!G22:G24) -> 803.68 | D37: =SUM('Data Sheet'!H22:H24) -> 1222.73 | E37: =SUM('Data Sheet'!I22:I24) -> 2051.86 | F37: =SUM('Data Sheet'!J22:J24) -> 2951.78 | G37: =SUM('Data Sheet'!K22:K24) -> 3905.85
B38: % of revenue | C38: =C37/C31 -> 0.30994693 | D38: =D37/D31 -> 0.27183739 | E38: =E37/E31 -> 0.24895111 | F38: =F37/F31 -> 0.23852556 | G38: =G37/G31 -> 0.22795091
B39: EBITDA | C39: =C35-C37 -> 113.87 | D39: =D35-D37 -> 594.72 | E39: =E35-E37 -> 1114.15 | F39: =F35-F37 -> 1970.69 | G39: =G35-G37 -> 2819.96
B40: % margin | C40: =C39/C31 -> 0.043915062 | D40: =D39/D31 -> 0.13221818 | E40: =E39/E31 -> 0.13517924 | F40: =F39/F31 -> 0.15924626 | G40: =G39/G31 -> 0.16457684
B41: Depreciation | C41: ='Data Sheet'!G26 -> 257.3 | D41: ='Data Sheet'!H26 -> 310.82 | E41: ='Data Sheet'!I26 -> 493.69 | F41: ='Data Sheet'!J26 -> 671.11 | G41: ='Data Sheet'!K26 -> 895.18
B42: % of sales | C42: =C41/C31 -> 0.099230223 | D42: =D41/D31 -> 0.069101516 | E42: =E41/E31 -> 0.059899151 | F42: =F41/F31 -> 0.054230629 | G42: =G41/G31 -> 0.052243967
B43: EBIT | C43: =C39-C41 -> -143.43 | D43: =D39-D41 -> 283.9 | E43: =E39-E41 -> 620.46 | F43: =F39-F41 -> 1299.58 | G43: =G39-G41 -> 1924.78
B44: % margin | C44: =C43/C31 -> -0.055315161 | D44: =D43/D31 -> 0.06311666 | E44: =E43/E31 -> 0.075280089 | F44: =F43/F31 -> 0.10501563 | G44: =G43/G31 -> 0.11233287
B45: Other Income | C45: ='Data Sheet'!G25 -> 199.4 | D45: ='Data Sheet'!H25 -> 152.16 | E45: ='Data Sheet'!I25 -> 340.6 | F45: ='Data Sheet'!J25 -> 988.91 | G45: ='Data Sheet'!K25 -> 305.06
B46: Interest | C46: ='Data Sheet'!G27 -> 260.79 | D46: ='Data Sheet'!H27 -> 324.84 | E46: ='Data Sheet'!I27 -> 408.99 | F46: ='Data Sheet'!J27 -> 367.66 | G46: ='Data Sheet'!K27 -> 200.1
B47: % of debt | C47: =C46/'Data Sheet'!G59 -> 0.86950288 | D47: =D46/'Data Sheet'!H59 -> 0.068743969 | E47: =E46/'Data Sheet'!I59 -> 0.09161675 | F47: =F46/'Data Sheet'!J59 -> 0.20973308 | G47: =G46/'Data Sheet'!K59 -> 0.08944256
B48: Profit before tax | C48: =C43+C45-C46 -> -204.82 | D48: =D43+D45-D46 -> 111.22 | E48: =E43+E45-E46 -> 552.07 | F48: =F43+F45-F46 -> 1920.83 | G48: =G43+G45-G46 -> 2029.74
B49: % of revenue | C49: =C48/C31 -> -0.078990806 | D49: =D48/D31 -> 0.024726435 | E49: =E48/E31 -> 0.066982366 | F49: =F48/F31 -> 0.15521721 | G49: =G48/G31 -> 0.11845849
B50: Tax | C50: ='Data Sheet'!G29 -> -58.65 | D50: ='Data Sheet'!H29 -> 5.39 | E50: ='Data Sheet'!I29 -> 107.44 | F50: ='Data Sheet'!J29 -> 434.03 | G50: ='Data Sheet'!K29 -> 483.02
...

Sheet Comps
B1: COMPARABLE COMPANY ANALYSIS
B2: Financial Modelling
B6: Comps Data
B8: Company | C8: Ticker | D8: Price | E8: Market Cap | F8: Sales | G8: EBITDA | H8: Net Income | I8: Beta | J8: Total Debt | K8: Cash & Cash Equivalents | L8: EV/EBITDA | M8: P/E
B9: Trent Limited | C9: TRENT | D9: 4791 | E9: 170282 | F9: 17135 | G9: 9270 | H9: 1448 | I9: 0.79 | J9: 2237 | K9: 973 | L9: 110.1 | M9: 102.3
B10: Avenue Supermarts (DMART) | C10: DMART | D10: 4274 | E10: 278260 | F10: 59358 | G10: 22940 | H10: 2707 | I10: 0.63 | J10: 1609 | K10: 210 | L10: 101.3 | M10: 93.4
B11: Vishal Mega Mart | C11: VMM | D11: 148 | E11: 69155 | F11: 10716 | G11: 2730 | H11: 632 | I11: 0.92 | J11: 1093 | K11: 986 | L11: 109.6 | M11: 133.4
B12: Aditya Birla Lifestyle Brands | C12: ABLBL | D12: 139 | E12: 16959 | F12: 7830 | G12: 820 | H12: 59.6 | I12: 0.88 | J12: 512 | K12: 407 | L12: 283.5 | M12: 123
B13: Vedant Fashions (Manyavar) | C13: MANYAVAR | D13: 688 | E13: 16720 | F13: 1386 | G13: 610 | H13: 388 | I13: 0.55 | J13: 483 | K13: 726 | L13: 42.3 | M13: 87.9
B15: Industry Beta
C17: Equity | D17: Total | E17: Debt/ | F17: Debt/ | G17: Tax | H17: Levered | I17: Unlevered
B18: Company Name | C18: Value | D18: Debt | E18: Equity | F18: Capital | G18: Rate % | H18: Beta | I18: Beta
B19: =B10 -> Avenue Supermarts (DMART) | C19: =E10 -> 278260 | D19: =J10 -> 1609 | E19: =D19/C19 -> 0.0057823618 | F19: =D19/(C19+D19) -> 0.0057491183 | G19: =Tax_rate -> 0.25 | H19: =I10 -> 0.63 | I19: =H19/(1+E19*(1-Tax_rate)) -> 0.62727963
B20: =B11 -> Vishal Mega Mart | C20: =E11 -> 69155 | D20: =J11 -> 1093 | E20: =D20/C20 -> 0.015805076 | F20: =D20/(C20+D20) -> 0.015559162 | G20: =Tax_rate -> 0.25 | H20: =I11 -> 0.92 | I20: =H20/(1+E20*(1-Tax_rate)) -> 0.90922226
B21: =B12 -> Aditya Birla Lifestyle Brands | C21: =E12 -> 16959 | D21: =J12 -> 512 | E21: =D21/C21 -> 0.030190459 | F21: =D21/(C21+D21) -> 0.029305707 | G21: =Tax_rate -> 0.25 | H21: =I12 -> 0.88 | I21: =H21/(1+E21*(1-Tax_rate)) -> 0.86051548
B22: =B13 -> Vedant Fashions (Manyavar) | C22: =E13 -> 16720 | D22: =J13 -> 483 | E22: =D22/C22 -> 0.02888756 | F22: =D22/(C22+D22) -> 0.028076498 | G22: =Tax_rate -> 0.25 | H22: =I13 -> 0.55 | I22: =H22/(1+E22*(1-Tax_rate)) -> 0.53833658
B23: Average | E23: =AVERAGE(E19:E22) -> 0.020166364 | F23: =AVERAGE(F19:F22) -> 0.019672621 | G23: =AVERAGE(G19:G22) -> 0.25 | H23: =AVERAGE(H19:H22) -> 0.745 | I23: =AVERAGE(I19:I22) -> 0.73383849
B24: Median | E24: =MEDIAN(E19:E22) -> 0.022346318 | F24: =MEDIAN(F19:F22) -> 0.02181783 | G24: =MEDIAN(G19:G22) -> 0.25 | H24: =MEDIAN(H19:H22) -> 0.755 | I24: =MEDIAN(I19:I22) -> 0.74389756
B26: Comparable Companies Analysis
D28: Market Data | J28: Financial Data | M28: Valuation
D29: Price | E29: Shares | F29: Market Cap | G29: Debt | H29: Cash | I29: EV | J29: Sales | K29: EBITDA | L29: Earnings | M29: EV/Sales | N29: EV/EBITDA | O29: P/E
B30: Company Name | C30: Ticker | D30: (₹/share) | E30: Crs | F30: ₹ Crs | G30: ₹ Crs | H30: & Equivalents | I30: ₹ Crs | J30: ₹ Crs | K30: ₹ Crs | L30: ₹ Crs | M30: x | N30: x | O30: x
B31: =B10 -> Avenue Supermarts (DMART) | C31: =C10 -> DMART | D31: =D10 -> 4274 | E31: =F31/D31 -> 65.105288 | F31: =E10 -> 278260 | G31: =J10 -> 1609 | H31: =K10 -> 210 | I31: =F31+G31-H31 -> 279659 | J31: =F10 -> 59358 | K31: =G10 -> 22940 | L31: =H10 -> 2707 | M31: =I31/J31 -> 4.7113953 | N31: =I31/K31 -> 12.190889 | O31: =F31/L31 -> 102.79276
B32: =B11 -> Vishal Mega Mart | C32: =C11 -> VMM | D32: =D11 -> 148 | E32: =F32/D32 -> 467.26351 | F32: =E11 -> 69155 | G32: =J11 -> 1093 | H32: =K11 -> 986 | I32: =F32+G32-H32 -> 69262 | J32: =F11 -> 10716 | K32: =G11 -> 2730 | L32: =H11 -> 632 | M32: =I32/J32 -> 6.4634192 | N32: =I32/K32 -> 25.370696 | O32: =F32/L32 -> 109.42247
B33: =B12 -> Aditya Birla Lifestyle Brands | C33: =C12 -> ABLBL | D33: =D12 -> 139 | E33: =F33/D33 -> 122.00719 | F33: =E12 -> 16959 | G33: =J12 -> 512 | H33: =K12 -> 407 | I33: =F33+G33-H33 -> 17064 | J33: =F12 -> 7830 | K33: =G12 -> 820 | L33: =H12 -> 59.6 | M33: =I33/J33 -> 2.1793103 | N33: =I33/K33 -> 20.809756 | O33: =F33/L33 -> 284.54698
B34: =B13 -> Vedant Fashions (Manyavar) | C34: =C13 -> MANYAVAR | D34: =D13 -> 688 | E34: =F34/D34 -> 24.302326 | F34: =E13 -> 16720 | G34: =J13 -> 483 | H34: =K13 -> 726 | I34: =F34+G34-H34 -> 16477 | J34: =F13 -> 1386 | K34: =G13 -> 610 | L34: =H13 -> 388 | M34: =I34/J34 -> 11.888167 | N34: =I34/K34 -> 27.011475 | O34: =F34/L34 -> 43.092784
B36: Average | M36: =AVERAGE(M31:M34) -> 6.310573 | N36: =AVERAGE(N31:N34) -> 21.345704 | O36: =AVERAGE(O31:O34) -> 134.96375
B37: Median | M37: =MEDIAN(M31:M34) -> 5.5874072 | N37: =MEDIAN(N31:N34) -> 23.090226 | O37: =MEDIAN(O31:O34) -> 106.10761
B39: =B9 -> Trent Limited | C39: =C9 -> TRENT | D39: =D9 -> 4791 | E39: =F39/D39 -> 35.542058 | F39: =E9 -> 170282 | G39: =J9 -> 2237 | H39: =K9 -> 973 | I39: =F39+G39-H39 -> 171546 | J39: =F9 -> 17135 | K39: =G9 -> 9270 | L39: =H9 -> 1448 | M39: =I39/J39 -> 10.011439 | N39: =I39/K39 -> 18.505502 | O39: =F39/L39 -> 117.59807
B41: Metric | C41: Comps | D41: EV | E41: Net Debt | F41: Equity Value | G41: Shares | H41: Share Price
B42: EV/Sales | C42: {=TRANSPOSE(M37:O37)} -> 5.5874072 | D42: =J39*C42 -> 95740.223 | E42: =$G$39-$H$39 -> 1264 | F42: =D42-E42 -> 94476.223 | G42: =$E$39 -> 35.542058 | H42: =F42/G42 -> 2658.1528
B43: EV/EBITDA | C43: 23.090226 | D43: =K39*C43 -> 214046.4 | E43: =$G$39-$H$39 -> 1264 | F43: =D43-E43 -> 212782.4 | G43: =$E$39 -> 35.542058 | H43: =F43/G43 -> 5986.7776
B44: PE Ratio | C44: 106.10761 | D44: =F44+E44 -> 154907.82 | E44: =$G$39-$H$39 -> 1264 | F44: =C44*L39 -> 153643.82 | G44: =$E$39 -> 35.542058 | H44: =F44/G44 -> 4322.8736

Sheet Data Sheet
A1: COMPANY NAME | E1: =IF(B2<>B3, "A NEW VERSION OF THE WORKSHEET IS AVAILABLE", "")
A2: LATEST VERSION | B2: 2.1 | E2: PLEASE DO NOT MAKE ANY CHANGES TO THIS SHEET
A3: CURRENT VERSION | B3: 2.1
A5: META
A6: Number of shares | B6: Company Overview
A7: Face Value | B7: 1
A8: Current Price | B8: 4789.6
A9: Market Capitalization | B9: 170264.27
A15: PROFIT & LOSS
A16: Report Date | B16: 42460 | C16: 42825 | D16: 43190 | E16: 43555 | F16: 43921 | G16: 44286 | H16: 44651 | I16: 45016 | J16: 45382 | K16: 45747
A17: Sales | B17: 1686.17 | C17: 1812.44 | D17: 2157.46 | E17: 2630.24 | F17: 3485.98 | G17: 2592.96 | H17: 4498.02 | I17: 8242.02 | J17: 12375.11 | K17: 17134.61
A18: Raw Material Cost | B18: 810.2 | C18: 911.22 | D18: 1070.02 | E18: 1459.67 | F18: 1951.64 | G18: 1371.64 | H18: 2920.38 | I18: 5211.05 | J18: 7123.6 | K18: 10143.39
A19: Change in Inventory | B19: 14.59 | C19: 29.86 | D19: 38.51 | E19: 148.23 | F19: 69.89 | G19: -162.36 | H19: 438.84 | I19: 491.31 | J19: 164.71 | K19: 454.25
A20: Power and Fuel | B20: 48.92 | C20: 51.28 | D20: 52.75 | E20: 59.18 | F20: 66.64 | G20: 49.41 | H20: 71.89 | I20: 144.28 | J20: 229.16 | K20: 349.87
A21: Other Mfr. Exp | B21: 76.42 | C21: 81.91 | D21: 90.78 | E21: 122.09 | F21: 97.51 | G21: 92 | H21: 127.14 | I21: 211.99 | J21: 264.59 | K21: 369.79
A22: Employee Cost | B22: 165.69 | C22: 194.72 | D22: 233.02 | E22: 288.89 | F22: 361.01 | G22: 303.4 | H22: 402.92 | I22: 659.07 | J22: 1041.74 | K22: 1315.54
A23: Selling and admin | B23: 444.06 | C23: 407.07 | D23: 450.61 | E23: 514.41 | F23: 436.82 | G23: 364.62 | H23: 705.03 | I23: 1252.53 | J23: 1709.55 | K23: 2322.83
A24: Other Expenses | B24: 65.71 | C24: 62.57 | D24: 90.29 | E24: 93.59 | F24: 113.28 | G24: 135.66 | H24: 114.78 | I24: 140.26 | J24: 200.49 | K24: 267.48
A25: Other Income | B25: 86.44 | C25: 81.31 | D25: 27.47 | E25: 30.14 | F25: 146.63 | G25: 199.4 | H25: 152.16 | I25: 340.6 | J25: 988.91 | K25: 305.06
A26: Depreciation | B26: 38.59 | C26: 41.29 | D26: 45.53 | E26: 51.67 | F26: 247.24 | G26: 257.3 | H26: 310.82 | I26: 493.69 | J26: 671.11 | K26: 895.18
A27: Interest | B27: 47.73 | C27: 45.55 | D27: 43.78 | E27: 50.64 | F27: 263.37 | G27: 260.79 | H27: 324.84 | I27: 408.99 | J27: 367.66 | K27: 200.1
... A31: Dividend Amount | B31: 29.91 | C31: 33.23 | D31: 38.21 | E31: 43.2 | F31: 35.55 | G31: 21.33 | H31: 60.44 | I31: 78.21 | J31: 113.76 | K31: 177.75
C35: =C31-C33 -> 33.23
A40: Quarters
A41: Report Date | B41: 45016 | C41: 45107 | D41: 45199 | E41: 45291 | F41: 45382 | G41: 45473 | H41: 45565 | I41: 45657 | J41: 45747 | K41: 45838
A42: Sales | B42: 2182.75 | C42: 2628.37 | D42: 2982.42 | E42: 3466.62 | F42: 3297.7 | G42: 4104.44 | H42: 4156.67 | I42: 4656.56 | J42: 4216.94 | K42: 4883.48
A43: Expenses | B43: 1979.73 | C43: 2260.97 | D43: 2525.85 | E43: 2838.1 | F43: 2828.06 | G43: 3491.09 | H43: 3513.66 | I43: 3809.19 | J43: 3566.03 | K43: 4035.62
A44: Other Income | B44: 88.91 | C44: 78.61 | D44: 105.42 | E44: 110.01 | F44: 694.87 | G44: 100.91 | H44: 53.75 | I44: 79.87 | J44: 74.34 | K44: 49.8
A45: Depreciation | B45: 136.57 | C45: 141.42 | D45: 152.22 | E45: 164.53 | F45: 212.94 | G45: 181.32 | H45: 196.95 | I45: 244.93 | J45: 271.98 | K45: 292.93
A46: Interest | B46: 91.59 | C46: 92.3 | D46: 95.45 | E46: 98.81 | F46: 32.54 | G46: 31.55 | H46: 33 | I46: 36.52 | J46: 37.52 | K46: 40.04
A47: Profit before tax | B47: 63.77 | C47: 212.29 | D47: 314.32 | E47: 475.19 | F47: 919.03 | G47: 501.39 | H47: 466.81 | I47: 645.79 | J47: 415.75 | K47: 564.69
A48: Tax | B48: 18.82 | C48: 45.62 | D48: 86.26 | E48: 104.55 | F48: 206.94 | G48: 110.18 | H48: 131.75 | I48: 149.25 | J48: 104.15 | K48: 139.99
A49: Net profit | B49: 54.1 | C49: 173.48 | D49: 234.73 | E49: 374.36 | F49: 704.23 | G49: 392.57 | H49: 338.75 | I49: 497.25 | J49: 318.15 | K49: 429.69
A50: Operating Profit | B50: 203.02 | C50: 367.4 | D50: 456.57 | E50: 628.52 | F50: 469.64 | G50: 613.35 | H50: 643.01 | I50: 847.37 | J50: 650.91 | K50: 847.86
A55: BALANCE SHEET
A56: Report Date | B56: 42460 | C56: 42825 | D56: 43190 | E56: 43555 | F56: 43921 | G56: 44286 | H56: 44651 | I56: 45016 | J56: 45382 | K56: 45747
A57: Equity Share Capital | B57: 33.23 | C57: 33.23 | D57: 33.23 | E57: 33.23 | F57: 35.55 | G57: 35.55 | H57: 35.55 | I57: 35.55 | J57: 35.55 | K57: 35.55
A58: Reserves | B58: 1431.16 | C58: 1514.46 | D58: 1562.14 | E58: 1613.28 | F58: 2352.22 | G58: 2277.48 | H58: 2328.45 | I58: 2559.94 | J58: 4032.19 | K58: 5426.19
A59: Borrowings | B59: 399.8 | C59: 391.74 | D59: 391.43 | E59: 494.14 | F59: 299.74 | G59: 299.93 | H59: 4725.36 | I59: 4464.14 | J59: 1752.99 | K59: 2237.19
A60: Other Liabilities | B60: 292.4 | C60: 282.82 | D60: 349.06 | E60: 418.11 | F60: 2819.17 | G60: 3110.77 | H60: 636.66 | I60: 1021.9 | J60: 1341.02 | K60: 1720.71
...
